<?xml version="1.0" ?>
<!-- =================================================================================== -->
<!-- |    This document was autogenerated by xacro from wheely_boi.xacro               | -->
<!-- |    EDITING THIS FILE BY HAND IS NOT RECOMMENDED                                 | -->
<!-- =================================================================================== -->
<robot name="wheely_boi">
  <gazebo reference="edumip_body">
    <material>Gazebo/White</material>
    <mu1>0.2</mu1>
    <mu2>0.2</mu2>
  </gazebo>
  <gazebo reference="wheelR">
    <material>Gazebo/Red</material>
    <mu1>0.84</mu1>
    <mu2>0.84</mu2>
  </gazebo>
  <gazebo reference="wheelL">
    <material>Gazebo/Blue</material>
    <mu1>0.84</mu1>
    <mu2>0.84</mu2>
  </gazebo>
  <link name="edumip_body">
    <visual>
      <geometry>
        <box size="0.035 0.05 0.1"/>
      </geometry>
    </visual>
    <collision>
      <geometry>
        <box size="0.035 0.05 0.1"/>
      </geometry>
    </collision>
    <inertial>
      <mass value="0.18"/>
      <inertia ixx="6.0e-4" ixy="0" ixz="0" iyy="6.0e-4" iyz="0" izz="6.0e-4"/>
    </inertial>
  </link>
  <link name="wheelL">
    <visual>
      <geometry>
        <cylinder length="0.01" radius="0.034"/>
      </geometry>
    </visual>
    <collision>
      <geometry>
        <cylinder length="0.01" radius="0.034"/>
      </geometry>
    </collision>
    <inertial>
      <mass value="0.03"/>
      <inertia ixx="1.75e-5" ixy="0.0" ixz="0.0" iyy="1.75e-5" iyz="0.0" izz="1.75e-5"/>
    </inertial>
  </link>
  <link name="wheelR">
    <visual>
      <geometry>
        <cylinder length="0.01" radius="0.034"/>
      </geometry>
    </visual>
    <collision>
      <geometry>
        <cylinder length="0.01" radius="0.034"/>
      </geometry>
    </collision>
    <inertial>
      <mass value="0.03"/>
      <inertia ixx="1.75e-5" ixy="0.0" ixz="0.0" iyy="1.75e-5" iyz="0.0" izz="1.75e-5"/>
    </inertial>
  </link>
  <joint name="jointL" type="continuous">
    <parent link="edumip_body"/>
    <child link="wheelL"/>
    <axis xyz="0 0 1"/>
    <origin rpy="1.5707963267948966 0 0" xyz="0 0.030000000000000002 -0.04"/>
    <dynamics friction="0.1"/>
  </joint>
  <joint name="jointR" type="continuous">
    <parent link="edumip_body"/>
    <child link="wheelR"/>
    <axis xyz="0 0 1"/>
    <origin rpy="1.5707963267948966 0 0" xyz="0 -0.030000000000000002 -0.04"/>
    <dynamics friction="0.1"/>
  </joint>
  <gazebo>
    <plugin filename="libwb_plugin.so" name="wb_plugin"> </plugin>
  </gazebo>
</robot>

